Workbook
Name AL: 'MRR Cohort'!$C$2

Sheet Dashboard
A1: SaaS COHORT ANALYSIS — DASHBOARD
A3: KEY ASSUMPTIONS
A4: Starting MRR per Customer | B4: 100
A5: Monthly Churn Rate | B5: 0.07
A6: Monthly Expansion Rate | B6: 0.025
A7: Net Revenue Retention (Monthly) | B7: =1-B5+B6 -> 0.955
A8: Net Revenue Retention (Annual) | B8: =(1-B5+B6)^12 -> 0.57549355
A9: Total Cohorts | B9: 36
A10: Total Customers (Target) | B10: 50
A11: Model Start Date | B11: 44927
A13: COHORT VIEW SELECTOR | D13: Views List
A14: Select View: | B14: Retention % | D14: Retention %
D15: MRR ($)
A16: KEY PERFORMANCE INDICATORS | D16: Churned Customers
A17: Total Active Customers | B17: Total MRR (Month 36) | C17: Avg MRR / Customer | D17: Cumulative Revenue | E17: Avg Customer LTV | F17: Net Revenue Retention | G17: Total Churned
A18: ='MRR Waterfall'!G37 -> 16.680033 | B18: ='MRR Waterfall'!B38 -> 2378.19 | C18: =IF(A18>0,B18/A18,0) -> 142.57706 | D18: =SUM('MRR Waterfall'!B3:B38) -> 62918.824 | E18: =IF(Dashboard!B10>0,D18/Dashboard!B10,0) -> 1258.3765 | F18: =Dashboard!B8 -> 0.57549355 | G18: =Dashboard!B10-A18 -> 33.319967
A20: HOW TO USE THIS MODEL
A21: 1. Adjust blue assumptions above (MRR, churn rate, expansion rate) to model different scenarios
A22: 2. Use the dropdown in B14 to switch between 5 cohort views in the 'Cohort Analysis' tab
A23: 3. Available views: Retention %, MRR ($), Churned Customers, Cumulative Revenue ($), LTV per Customer ($)
A24: 4. The 'MRR Waterfall' tab shows monthly MRR breakdown with charts
A25: 5. All values update dynamically — change any assumption and the entire model recalculates
A26: 6. Conditional formatting heatmap on cohort data adjusts to each view automatically
A28: RETENTION CURVE
A29: Month | B29: Retention %
A30: Month 0 | B30: =(1-B5)^0 -> 1
A31: Month 1 | B31: =(1-B5)^1 -> 0.93
A32: Month 2 | B32: =(1-B5)^2 -> 0.8649
A33: Month 3 | B33: =(1-B5)^3 -> 0.804357
A34: Month 4 | B34: =(1-B5)^4 -> 0.74805201
A35: Month 5 | B35: =(1-B5)^5 -> 0.69568837
A36: Month 6 | B36: =(1-B5)^6 -> 0.64699018
A37: Month 7 | B37: =(1-B5)^7 -> 0.60170087
A38: Month 8 | B38: =(1-B5)^8 -> 0.55958181
A39: Month 9 | B39: =(1-B5)^9 -> 0.52041108
A40: Month 10 | B40: =(1-B5)^10 -> 0.48398231
A41: Month 11 | B41: =(1-B5)^11 -> 0.45010355
A42: Month 12 | B42: =(1-B5)^12 -> 0.4185963
A43: Month 13 | B43: =(1-B5)^13 -> 0.38929456
A44: Month 14 | B44: =(1-B5)^14 -> 0.36204394
...

Sheet Cohort Analysis
A1: Cohort | B1: New Customers | C1: Month 0 | D1: Month 1 | E1: Month 2 | F1: Month 3 | G1: Month 4 | H1: Month 5 | I1: Month 6 | J1: Month 7 | K1: Month 8 | L1: Month 9 | M1: Month 10 | N1: Month 11 | O1: Month 12 | P1: Month 13 | Q1: Month 14 | R1: Month 15 | S1: Month 16 | T1: Month 17 | U1: Month 18 | V1: Month 19 | W1: Month 20 | X1: Month 21 | Y1: Month 22 | Z1: Month 23 | AA1: Month 24 | AB1: Month 25 | AC1: Month 26 | AD1: Month 27 | AE1: Month 28 | AF1: Month 29 | AG1: Month 30 | AH1: Month 31 | AI1: Month 32 | AJ1: Month 33 | AK1: Month 34 | AL1: Month 35
C2: 0 | D2: 1 | E2: 2 | F2: 3 | G2: 4 | H2: 5 | I2: 6 | J2: 7 | K2: 8 | L2: 9 | M2: 10 | N2: 11 | O2: 12 | P2: 13 | Q2: 14 | R2: 15 | S2: 16 | T2: 17 | U2: 18 | V2: 19 | W2: 20 | X2: 21 | Y2: 22 | Z2: 23 | AA2: 24 | AB2: 25 | AC2: 26 | AD2: 27 | AE2: 28 | AF2: 29 | AG2: 30 | AH2: 31 | AI2: 32 | AJ2: 33 | AK2: 34 | AL2: 35
A3: Jan '23 Cohort | B3: 1 | C3: =IF(Dashboard!$B$14="Retention %",1,IF(Dashboard!$B$14="MRR ($)",$B3*Dashboard!$B$4,IF(Dashboard!$B$14="Churned Customers",0,IF(Dashboard!$B$14="Cumulative Revenue ($)",$B3*Dashboard!$B$4,IF(Dashboard!$B$14="LTV per Customer ($)",IF($B3>0,Dashboard!$B$4,0),""))))) -> 1 | D3: =IF(Dashboard!$B$14="Retention %",(1-Dashboard!$B$5)^1,IF(Dashboard!$B$14="MRR ($)",$B3*Dashboard!$B$4*(1-Dashboard!$B$5+Dashboard!$B$6)^1,IF(Dashboard!$B$14="Churned Customers",$B3*(1-(1-Dashboard!$B$5)^1),IF(Dashboard!$B$14="Cumulative Revenue ($)",$B3*Dashboard!$B$4*IF(Dashboard!$B$5=Dashboard!$B$6,2,((1-Dashboard!$B$5+Dashboard!$B$6)^2-1)/(Dashboard!$B$6-Dashboard!$B$5)),IF(Dashboard!$B$14="LTV per Customer ($)",IF($B3>0,Dashboard!$B$4*IF(Dashboard!$B$5=Dashboard!$B$6,2,((1-Dashboard!$B$5+Dashboard!$B$6)^2-1)/(Dashboard!$B$6-Dashboard!$B$5)),0),""))))) -> 0.93 | E3: =IF(Dashboard!$B$14="Retention %",(1-Dashboard!$B$5)^2,IF(Dashboard!$B$14="MRR ($)",$B3*Dashboard!$B$4*(1-Dashboard!$B$5+Dashboard!$B$6)^2,IF(Dashboard!$B$14="Churned Customers",$B3*(1-(1-Dashboard!$B$5)^2),IF(Dashboard!$B$14="Cumulative Revenue ($)",$B3*Dashboard!$B$4*IF(Dashboard!$B$5=Dashboard!$B$6,3,((1-Dashboard!$B$5+Dashboard!$B$6)^3-1)/(Dashboard!$B$6-Dashboard!$B$5)),IF(Dashboard!$B$14="LTV per Customer ($)",IF($B3>0,Dashboard!$B$4*IF(Dashboard!$B$5=Dashboard!$B$6,3,((1-Dashboard!$B$5+Dashboard!$B$6)^3-1)/(Dashboard!$B$6-Dashboard!$B$5)),0),""))))) -> 0.8649 | F3: =IF(Dashboard!$B$14="Retention %",(1-Dashboard!$B$5)^3,IF(Dashboard!$B$14="MRR ($)",$B3*Dashboard!$B$4*(1-Dashboard!$B$5+Dashboard!$B$6)^3,IF(Dashboard!$B$14="Churned Customers",$B3*(1-(1-Dashboard!$B$5)^3),IF(Dashboard!$B$14="Cumulative Revenue ($)",$B3*Dashboard!$B$4*IF(Dashboard!$B$5=Dashboard!$B$6,4,((1-Dashboard!$B$5+Dashboard!$B$6)^4-1)/(Dashboard!$B$6-Dashboard!$B$5)),IF(Dashboard!$B$14="LTV per Customer ($)",IF($B3>0,Dashboard!$B$4*IF(Dashboard!$B$5=Dashboard!$B$6,4,((1-Dashboard!$B$5+Dashboard!$B$6)^4-1)/(Dashboard!$B$6-Dashboard!$B$5)),0),""))))) -> 0.804357 | G3: =IF(Dashboard!$B$14="Retention %",(1-Dashboard!$B$5)^4,IF(Dashboard!$B$14="MRR ($)",$B3*Dashboard!$B$4*(1-Dashboard!$B$5+Dashboard!$B$6)^4,IF(Dashboard!$B$14="Churned Customers",$B3*(1-(1-Dashboard!$B$5)^4),IF(Dashboard!$B$14="Cumulative Revenue ($)",$B3*Dashboard!$B$4*IF(Dashboard!$B$5=Dashboard!$B$6,5,((1-Dashboard!$B$5+Dashboard!$B$6)^5-1)/(Dashboard!$B$6-Dashboard!$B$5)),IF(Dashboard!$B$14="LTV per Customer ($)",IF($B3>0,Dashboard!$B$4*IF(Dashboard!$B$5=Dashboard!$B$6,5,((1-Dashboard!$B$5+Dashboard!$B$6)^5-1)/(Dashboard!$B$6-Dashboard!$B$5)),0),""))))) -> 0.74805201 | H3: =IF(Dashboard!$B$14="Retention %",(1-Dashboard!$B$5)^5,IF(Dashboard!$B$14="MRR ($)",$B3*Dashboard!$B$4*(1-Dashboard!$B$5+Dashboard!$B$6)^5,IF(Dashboard!$B$14="Churned Customers",$B3*(1-(1-Dashboard!$B$5)^5),IF(Dashboard!$B$14="Cumulative Revenue ($)",$B3*Dashboard!$B$4*IF(Dashboard!$B$5=Dashboard!$B$6,6,((1-Dashboard!$B$5+Dashboard!$B$6)^6-1)/(Dashboard!$B$6-Dashboard!$B$5)),IF(Dashboard!$B$14="LTV per Customer ($)",IF($B3>0,Dashboard!$B$4*IF(Dashboard!$B$5=Dashboard!$B$6,6,((1-Dashboard!$B$5+Dashboard!$B$6)^6-1)/(Dashboard!$B$6-Dashboard!$B$5)),0),""))))) -> 0.69568837 | I3: =IF(Dashboard!$B$14="Retention %",(1-Dashboard!$B$5)^6,IF(Dashboard!$B$14="MRR ($)",$B3*Dashboard!$B$4*(1-Dashboard!$B$5+Dashboard!$B$6)^6,IF(Dashboard!$B$14="Churned Customers",$B3*(1-(1-Dashboard!$B$5)^6),IF(Dashboard!$B$14="Cumulative Revenue ($)",$B3*Dashboard!$B$4*IF(Dashboard!$B$5=Dashboard!$B$6,7,((1-Dashboard!$B$5+Dashboard!$B$6)^7-1)/(Dashboard!$B$6-Dashboard!$B$5)),IF(Dashboard!$B$14="LTV per Customer ($)",IF($B3>0,Dashboard!$B$4*IF(Dashboard!$B$5=Dashboard!$B$6,7,((1-Dashboard!$B$5+Dashboard!$B$6)^7-1)/(Dashboard!$B$6-Dashboard!$B$5)),0),""))))) -> 0.64699018 | J3: =IF(Dashboard!$B$14="Retention %",(1-Dashboard!$B$5)^7,IF(Dashboard!$B$14="MRR ($)",$B3*Dashboard!$B$4*(1-Dashboard!$B$5+Dashboard!$B$6)^7,IF(Dashboard!$B$14="Churned Customers",$B3*(1-(1-Dashboard!$B$5)^7),IF(Dashboard!$B$14="Cumulative Revenue ($)",$B3*Dashboard!$B$4*IF(Dashboard!$B$5=Dashboard!$B$6,8,((1-Dashboard!$B$5+Dashboard!$B$6)^8-1)/(Dashboard!$B$6-Dashboard!$B$5)),IF(Dashboard!$B$14="LTV per Customer ($)",IF($B3>0,Dashboard!$B$4*IF(Dashboard!$B$5=Dashboard!$B$6,8,((1-Dashboard!$B$5+Dashboard!$B$6)^8-1)/(Dashboard!$B$6-Dashboard!$B$5)),0),""))))) -> 0.60170087 | K3: =IF(Dashboard!$B$14="Retention %",(1-Dashboard!$B$5)^8,IF(Dashboard!$B$14="MRR ($)",$B3*Dashboard!$B$4*(1-Dashboard!$B$5+Dashboard!$B$6)^8,IF(Dashboard!$B$14="Churned Customers",$B3*(1-(1-Dashboard!$B$5)^8),IF(Dashboard!$B$14="Cumulative Revenue ($)",$B3*Dashboard!$B$4*IF(Dashboard!$B$5=Dashboard!$B$6,9,((1-Dashboard!$B$5+Dashboard!$B$6)^9-1)/(Dashboard!$B$6-Dashboard!$B$5)),IF(Dashboard!$B$14="LTV per Customer ($)",IF($B3>0,Dashboard!$B$4*IF(Dashboard!$B$5=Dashboard!$B$6,9,((1-Dashboard!$B$5+Dashboard!$B$6)^9-1)/(Dashboard!$B$6-Dashboard!$B$5)),0),""))))) -> 0.55958181 | L3: =IF(Dashboard!$B$14="Retention %",(1-Dashboard!$B$5)^9,IF(Dashboard!$B$14="MRR ($)",$B3*Dashboard!$B$4*(1-Dashboard!$B$5+Dashboard!$B$6)^9,IF(Dashboard!$B$14="Churned Customers",$B3*(1-(1-Dashboard!$B$5)^9),IF(Dashboard!$B$14="Cumulative Revenue ($)",$B3*Dashboard!$B$4*IF(Dashboard!$B$5=Dashboard!$B$6,10,((1-Dashboard!$B$5+Dashboard!$B$6)^10-1)/(Dashboard!$B$6-Dashboard!$B$5)),IF(Dashboard!$B$14="LTV per Customer ($)",IF($B3>0,Dashboard!$B$4*IF(Dashboard!$B$5=Dashboard!$B$6,10,((1-Dashboard!$B$5+Dashboard!$B$6)^10-1)/(Dashboard!$B$6-Dashboard!$B$5)),0),""))))) -> 0.52041108 | M3: =IF(Dashboard!$B$14="Retention %",(1-Dashboard!$B$5)^10,IF(Dashboard!$B$14="MRR ($)",$B3*Dashboard!$B$4*(1-Dashboard!$B$5+Dashboard!$B$6)^10,IF(Dashboard!$B$14="Churned Customers",$B3*(1-(1-Dashboard!$B$5)^10),IF(Dashboard!$B$14="Cumulative Revenue ($)",$B3*Dashboard!$B$4*IF(Dashboard!$B$5=Dashboard!$B$6,11,((1-Dashboard!$B$5+Dashboard!$B$6)^11-1)/(Dashboard!$B$6-Dashboard!$B$5)),IF(Dashboard!$B$14="LTV per Customer ($)",IF($B3>0,Dashboard!$B$4*IF(Dashboard!$B$5=Dashboard!$B$6,11,((1-Dashboard!$B$5+Dashboard!$B$6)^11-1)/(Dashboard!$B$6-Dashboard!$B$5)),0),""))))) -> 0.48398231 | N3: =IF(Dashboard!$B$14="Retention %",(1-Dashboard!$B$5)^11,IF(Dashboard!$B$14="MRR ($)",$B3*Dashboard!$B$4*(1-Dashboard!$B$5+Dashboard!$B$6)^11,IF(Dashboard!$B$14="Churned Customers",$B3*(1-(1-Dashboard!$B$5)^11),IF(Dashboard!$B$14="Cumulative Revenue ($)",$B3*Dashboard!$B$4*IF(Dashboard!$B$5=Dashboard!$B$6,12,((1-Dashboard!$B$5+Dashboard!$B$6)^12-1)/(Dashboard!$B$6-Dashboard!$B$5)),IF(Dashboard!$B$14="LTV per Customer ($)",IF($B3>0,Dashboard!$B$4*IF(Dashboard!$B$5=Dashboard!$B$6,12,((1-Dashboard!$B$5+Dashboard!$B$6)^12-1)/(Dashboard!$B$6-Dashboard!$B$5)),0),""))))) -> 0.45010355 | O3: =IF(Dashboard!$B$14="Retention %",(1-Dashboard!$B$5)^12,IF(Dashboard!$B$14="MRR ($)",$B3*Dashboard!$B$4*(1-Dashboard!$B$5+Dashboard!$B$6)^12,IF(Dashboard!$B$14="Churned Customers",$B3*(1-(1-Dashboard!$B$5)^12),IF(Dashboard!$B$14="Cumulative Revenue ($)",$B3*Dashboard!$B$4*IF(Dashboard!$B$5=Dashboard!$B$6,13,((1-Dashboard!$B$5+Dashboard!$B$6)^13-1)/(Dashboard!$B$6-Dashboard!$B$5)),IF(Dashboard!$B$14="LTV per Customer ($)",IF($B3>0,Dashboard!$B$4*IF(Dashboard!$B$5=Dashboard!$B$6,13,((1-Dashboard!$B$5+Dashboard!$B$6)^13-1)/(Dashboard!$B$6-Dashboard!$B$5)),0),""))))) -> 0.4185963 | P3: =IF(Dashboard!$B$14="Retention %",(1-Dashboard!$B$5)^13,IF(Dashboard!$B$14="MRR ($)",$B3*Dashboard!$B$4*(1-Dashboard!$B$5+Dashboard!$B$6)^13,IF(Dashboard!$B$14="Churned Customers",$B3*(1-(1-Dashboard!$B$5)^13),IF(Dashboard!$B$14="Cumulative Revenue ($)",$B3*Dashboard!$B$4*IF(Dashboard!$B$5=Dashboard!$B$6,14,((1-Dashboard!$B$5+Dashboard!$B$6)^14-1)/(Dashboard!$B$6-Dashboard!$B$5)),IF(Dashboard!$B$14="LTV per Customer ($)",IF($B3>0,Dashboard!$B$4*IF(Dashboard!$B$5=Dashboard!$B$6,14,((1-Dashboard!$B$5+Dashboard!$B$6)^14-1)/(Dashboard!$B$6-Dashboard!$B$5)),0),""))))) -> 0.38929456 | Q3: =IF(Dashboard!$B$14="Retention %",(1-Dashboard!$B$5)^14,IF(Dashboard!$B$14="MRR ($)",$B3*Dashboard!$B$4*(1-Dashboard!$B$5+Dashboard!$B$6)^14,IF(Dashboard!$B$14="Churned Customers",$B3*(1-(1-Dashboard!$B$5)^14),IF(Dashboard!$B$14="Cumulative Revenue ($)",$B3*Dashboard!$B$4*IF(Dashboard!$B$5=Dashboard!$B$6,15,((1-Dashboard!$B$5+Dashboard!$B$6)^15-1)/(Dashboard!$B$6-Dashboard!$B$5)),IF(Dashboard!$B$14="LTV per Customer ($)",IF($B3>0,Dashboard!$B$4*IF(Dashboard!$B$5=Dashboard!$B$6,15,((1-Dashboard!$B$5+Dashboard!$B$6)^15-1)/(Dashboard!$B$6-Dashboard!$B$5)),0),""))))) -> 0.36204394 | R3: =IF(Dashboard!$B$14="Retention %",(1-Dashboard!$B$5)^15,IF(Dashboard!$B$14="MRR ($)",$B3*Dashboard!$B$4*(1-Dashboard!$B$5+Dashboard!$B$6)^15,IF(Dashboard!$B$14="Churned Customers",$B3*(1-(1-Dashboard!$B$5)^15),IF(Dashboard!$B$14="Cumulative Revenue ($)",$B3*Dashboard!$B$4*IF(Dashboard!$B$5=Dashboard!$B$6,16,((1-Dashboard!$B$5+Dashboard!$B$6)^16-1)/(Dashboard!$B$6-Dashboard!$B$5)),IF(Dashboard!$B$14="LTV per Customer ($)",IF($B3>0,Dashboard!$B$4*IF(Dashboard!$B$5=Dashboard!$B$6,16,((1-Dashboard!$B$5+Dashboard!$B$6)^16-1)/(Dashboard!$B$6-Dashboard!$B$5)),0),""))))) -> 0.33670086 | S3: =IF(Dashboard!$B$14="Retention %",(1-Dashboard!$B$5)^16,IF(Dashboard!$B$14="MRR ($)",$B3*Dashboard!$B$4*(1-Dashboard!$B$5+Dashboard!$B$6)^16,IF(Dashboard!$B$14="Churned Customers",$B3*(1-(1-Dashboard!$B$5)^16),IF(Dashboard!$B$14="Cumulative Revenue ($)",$B3*Dashboard!$B$4*IF(Dashboard!$B$5=Dashboard!$B$6,17,((1-Dashboard!$B$5+Dashboard!$B$6)^17-1)/(Dashboard!$B$6-Dashboard!$B$5)),IF(Dashboard!$B$14="LTV per Customer ($)",IF($B3>0,Dashboard!$B$4*IF(Dashboard!$B$5=Dashboard!$B$6,17,((1-Dashboard!$B$5+Dashboard!$B$6)^17-1)/(Dashboard!$B$6-Dashboard!$B$5)),0),""))))) -> 0.3131318 | T3: =IF(Dashboard!$B$14="Retention %",(1-Dashboard!$B$5)^17,IF(Dashboard!$B$14="MRR ($)",$B3*Dashboard!$B$4*(1-Dashboard!$B$5+Dashboard!$B$6)^17,IF(Dashboard!$B$14="Churned Customers",$B3*(1-(1-Dashboard!$B$5)^17),IF(Dashboard!$B$14="Cumulative Revenue ($)",$B3*Dashboard!$B$4*IF(Dashboard!$B$5=Dashboard!$B$6,18,((1-Dashboard!$B$5+Dashboard!$B$6)^18-1)/(Dashboard!$B$6-Dashboard!$B$5)),IF(Dashboard!$B$14="LTV per Customer ($)",IF($B3>0,Dashboard!$B$4*IF(Dashboard!$B$5=Dashboard!$B$6,18,((1-Dashboard!$B$5+Dashboard!$B$6)^18-1)/(Dashboard!$B$6-Dashboard!$B$5)),0),""))))) -> 0.29121258 | U3: =IF(Dashboard!$B$14="Retention %",(1-Dashboard!$B$5)^18,IF(Dashboard!$B$14="MRR ($)",$B3*Dashboard!$B$4*(1-Dashboard!$B$5+Dashboard!$B$6)^18,IF(Dashboard!$B$14="Churned Customers",$B3*(1-(1-Dashboard!$B$5)^18),IF(Dashboard!$B$14="Cumulative Revenue ($)",$B3*Dashboard!$B$4*IF(Dashboard!$B$5=Dashboard!$B$6,19,((1-Dashboard!$B$5+Dashboard!$B$6)^19-1)/(Dashboard!$B$6-Dashboard!$B$5)),IF(Dashboard!$B$14="LTV per Customer ($)",IF($B3>0,Dashboard!$B$4*IF(Dashboard!$B$5=Dashboard!$B$6,19,((1-Dashboard!$B$5+Dashboard!$B$6)^19-1)/(Dashboard!$B$6-Dashboard!$B$5)),0),""))))) -> 0.2708277 | V3: =IF(Dashboard!$B$14="Retention %",(1-Dashboard!$B$5)^19,IF(Dashboard!$B$14="MRR ($)",$B3*Dashboard!$B$4*(1-Dashboard!$B$5+Dashboard!$B$6)^19,IF(Dashboard!$B$14="Churned Customers",$B3*(1-(1-Dashboard!$B$5)^19),IF(Dashboard!$B$14="Cumulative Revenue ($)",$B3*Dashboard!$B$4*IF(Dashboard!$B$5=Dashboard!$B$6,20,((1-Dashboard!$B$5+Dashboard!$B$6)^20-1)/(Dashboard!$B$6-Dashboard!$B$5)),IF(Dashboard!$B$14="LTV per Customer ($)",IF($B3>0,Dashboard!$B$4*IF(Dashboard!$B$5=Dashboard!$B$6,20,((1-Dashboard!$B$5+Dashboard!$B$6)^20-1)/(Dashboard!$B$6-Dashboard!$B$5)),0),""))))) -> 0.25186976 | W3: =IF(Dashboard!$B$14="Retention %",(1-Dashboard!$B$5)^20,IF(Dashboard!$B$14="MRR ($)",$B3*Dashboard!$B$4*(1-Dashboard!$B$5+Dashboard!$B$6)^20,IF(Dashboard!$B$14="Churned Customers",$B3*(1-(1-Dashboard!$B$5)^20),IF(Dashboard!$B$14="Cumulative Revenue ($)",$B3*Dashboard!$B$4*IF(Dashboard!$B$5=Dashboard!$B$6,21,((1-Dashboard!$B$5+Dashboard!$B$6)^21-1)/(Dashboard!$B$6-Dashboard!$B$5)),IF(Dashboard!$B$14="LTV per Customer ($)",IF($B3>0,Dashboard!$B$4*IF(Dashboard!$B$5=Dashboard!$B$6,21,((1-Dashboard!$B$5+Dashboard!$B$6)^21-1)/(Dashboard!$B$6-Dashboard!$B$5)),0),""))))) -> 0.23423887 | X3: =IF(Dashboard!$B$14="Retention %",(1-Dashboard!$B$5)^21,IF(Dashboard!$B$14="MRR ($)",$B3*Dashboard!$B$4*(1-Dashboard!$B$5+Dashboard!$B$6)^21,IF(Dashboard!$B$14="Churned Customers",$B3*(1-(1-Dashboard!$B$5)^21),IF(Dashboard!$B$14="Cumulative Revenue ($)",$B3*Dashboard!$B$4*IF(Dashboard!$B$5=Dashboard!$B$6,22,((1-Dashboard!$B$5+Dashboard!$B$6)^22-1)/(Dashboard!$B$6-Dashboard!$B$5)),IF(Dashboard!$B$14="LTV per Customer ($)",IF($B3>0,Dashboard!$B$4*IF(Dashboard!$B$5=Dashboard!$B$6,22,((1-Dashboard!$B$5+Dashboard!$B$6)^22-1)/(Dashboard!$B$6-Dashboard!$B$5)),0),""))))) -> 0.21784215 | Y3: =IF(Dashboard!$B$14="Retention %",(1-Dashboard!$B$5)^22,IF(Dashboard!$B$14="MRR ($)",$B3*Dashboard!$B$4*(1-Dashboard!$B$5+Dashboard!$B$6)^22,IF(Dashboard!$B$14="Churned Customers",$B3*(1-(1-Dashboard!$B$5)^22),IF(Dashboard!$B$14="Cumulative Revenue ($)",$B3*Dashboard!$B$4*IF(Dashboard!$B$5=Dashboard!$B$6,23,((1-Dashboard!$B$5+Dashboard!$B$6)^23-1)/(Dashboard!$B$6-Dashboard!$B$5)),IF(Dashboard!$B$14="LTV per Customer ($)",IF($B3>0,Dashboard!$B$4*IF(Dashboard!$B$5=Dashboard!$B$6,23,((1-Dashboard!$B$5+Dashboard!$B$6)^23-1)/(Dashboard!$B$6-Dashboard!$B$5)),0),""))))) -> 0.2025932 | Z3: =IF(Dashboard!$B$14="Retention %",(1-Dashboard!$B$5)^23,IF(Dashboard!$B$14="MRR ($)",$B3*Dashboard!$B$4*(1-Dashboard!$B$5+Dashboard!$B$6)^23,IF(Dashboard!$B$14="Churned Customers",$B3*(1-(1-Dashboard!$B$5)^23),IF(Dashboard!$B$14="Cumulative Revenue ($)",$B3*Dashboard!$B$4*IF(Dashboard!$B$5=Dashboard!$B$6,24,((1-Dashboard!$B$5+Dashboard!$B$6)^24-1)/(Dashboard!$B$6-Dashboard!$B$5)),IF(Dashboard!$B$14="LTV per Customer ($)",IF($B3>0,Dashboard!$B$4*IF(Dashboard!$B$5=Dashboard!$B$6,24,((1-Dashboard!$B$5+Dashboard!$B$6)^24-1)/(Dashboard!$B$6-Dashboard!$B$5)),0),""))))) -> 0.18841168 | AA3: =IF(Dashboard!$B$14="Retention %",(1-Dashboard!$B$5)^24,IF(Dashboard!$B$14="MRR ($)",$B3*Dashboard!$B$4*(1-Dashboard!$B$5+Dashboard!$B$6)^24,IF(Dashboard!$B$14="Churned Customers",$B3*(1-(1-Dashboard!$B$5)^24),IF(Dashboard!$B$14="Cumulative Revenue ($)",$B3*Dashboard!$B$4*IF(Dashboard!$B$5=Dashboard!$B$6,25,((1-Dashboard!$B$5+Dashboard!$B$6)^25-1)/(Dashboard!$B$6-Dashboard!$B$5)),IF(Dashboard!$B$14="LTV per Customer ($)",IF($B3>0,Dashboard!$B$4*IF(Dashboard!$B$5=Dashboard!$B$6,25,((1-Dashboard!$B$5+Dashboard!$B$6)^25-1)/(Dashboard!$B$6-Dashboard!$B$5)),0),""))))) -> 0.17522286 | AB3: =IF(Dashboard!$B$14="Retention %",(1-Dashboard!$B$5)^25,IF(Dashboard!$B$14="MRR ($)",$B3*Dashboard!$B$4*(1-Dashboard!$B$5+Dashboard!$B$6)^25,IF(Dashboard!$B$14="Churned Customers",$B3*(1-(1-Dashboard!$B$5)^25),IF(Dashboard!$B$14="Cumulative Revenue ($)",$B3*Dashboard!$B$4*IF(Dashboard!$B$5=Dashboard!$B$6,26,((1-Dashboard!$B$5+Dashboard!$B$6)^26-1)/(Dashboard!$B$6-Dashboard!$B$5)),IF(Dashboard!$B$14="LTV per Customer ($)",IF($B3>0,Dashboard!$B$4*IF(Dashboard!$B$5=Dashboard!$B$6,26,((1-Dashboard!$B$5+Dashboard!$B$6)^26-1)/(Dashboard!$B$6-Dashboard!$B$5)),0),""))))) -> 0.16295726 | AC3: =IF(Dashboard!$B$14="Retention %",(1-Dashboard!$B$5)^26,IF(Dashboard!$B$14="MRR ($)",$B3*Dashboard!$B$4*(1-Dashboard!$B$5+Dashboard!$B$6)^26,IF(Dashboard!$B$14="Churned Customers",$B3*(1-(1-Dashboard!$B$5)^26),IF(Dashboard!$B$14="Cumulative Revenue ($)",$B3*Dashboard!$B$4*IF(Dashboard!$B$5=Dashboard!$B$6,27,((1-Dashboard!$B$5+Dashboard!$B$6)^27-1)/(Dashboard!$B$6-Dashboard!$B$5)),IF(Dashboard!$B$14="LTV per Customer ($)",IF($B3>0,Dashboard!$B$4*IF(Dashboard!$B$5=Dashboard!$B$6,27,((1-Dashboard!$B$5+Dashboard!$B$6)^27-1)/(Dashboard!$B$6-Dashboard!$B$5)),0),""))))) -> 0.15155025 | AD3: =IF(Dashboard!$B$14="Retention %",(1-Dashboard!$B$5)^27,IF(Dashboard!$B$14="MRR ($)",$B3*Dashboard!$B$4*(1-Dashboard!$B$5+Dashboard!$B$6)^27,IF(Dashboard!$B$14="Churned Customers",$B3*(1-(1-Dashboard!$B$5)^27),IF(Dashboard!$B$14="Cumulative Revenue ($)",$B3*Dashboard!$B$4*IF(Dashboard!$B$5=Dashboard!$B$6,28,((1-Dashboard!$B$5+Dashboard!$B$6)^28-1)/(Dashboard!$B$6-Dashboard!$B$5)),IF(Dashboard!$B$14="LTV per Customer ($)",IF($B3>0,Dashboard!$B$4*IF(Dashboard!$B$5=Dashboard!$B$6,28,((1-Dashboard!$B$5+Dashboard!$B$6)^28-1)/(Dashboard!$B$6-Dashboard!$B$5)),0),""))))) -> 0.14094173 | AE3: =IF(Dashboard!$B$14="Retention %",(1-Dashboard!$B$5)^28,IF(Dashboard!$B$14="MRR ($)",$B3*Dashboard!$B$4*(1-Dashboard!$B$5+Dashboard!$B$6)^28,IF(Dashboard!$B$14="Churned Customers",$B3*(1-(1-Dashboard!$B$5)^28),IF(Dashboard!$B$14="Cumulative Revenue ($)",$B3*Dashboard!$B$4*IF(Dashboard!$B$5=Dashboard!$B$6,29,((1-Dashboard!$B$5+Dashboard!$B$6)^29-1)/(Dashboard!$B$6-Dashboard!$B$5)),IF(Dashboard!$B$14="LTV per Customer ($)",IF($B3>0,Dashboard!$B$4*IF(Dashboard!$B$5=Dashboard!$B$6,29,((1-Dashboard!$B$5+Dashboard!$B$6)^29-1)/(Dashboard!$B$6-Dashboard!$B$5)),0),""))))) -> 0.13107581 | AF3: =IF(Dashboard!$B$14="Retention %",(1-Dashboard!$B$5)^29,IF(Dashboard!$B$14="MRR ($)",$B3*Dashboard!$B$4*(1-Dashboard!$B$5+Dashboard!$B$6)^29,IF(Dashboard!$B$14="Churned Customers",$B3*(1-(1-Dashboard!$B$5)^29),IF(Dashboard!$B$14="Cumulative Revenue ($)",$B3*Dashboard!$B$4*IF(Dashboard!$B$5=Dashboard!$B$6,30,((1-Dashboard!$B$5+Dashboard!$B$6)^30-1)/(Dashboard!$B$6-Dashboard!$B$5)),IF(Dashboard!$B$14="LTV per Customer ($)",IF($B3>0,Dashboard!$B$4*IF(Dashboard!$B$5=Dashboard!$B$6,30,((1-Dashboard!$B$5+Dashboard!$B$6)^30-1)/(Dashboard!$B$6-Dashboard!$B$5)),0),""))))) -> 0.12190051 | AG3: =IF(Dashboard!$B$14="Retention %",(1-Dashboard!$B$5)^30,IF(Dashboard!$B$14="MRR ($)",$B3*Dashboard!$B$4*(1-Dashboard!$B$5+Dashboard!$B$6)^30,IF(Dashboard!$B$14="Churned Customers",$B3*(1-(1-Dashboard!$B$5)^30),IF(Dashboard!$B$14="Cumulative Revenue ($)",$B3*Dashboard!$B$4*IF(Dashboard!$B$5=Dashboard!$B$6,31,((1-Dashboard!$B$5+Dashboard!$B$6)^31-1)/(Dashboard!$B$6-Dashboard!$B$5)),IF(Dashboard!$B$14="LTV per Customer ($)",IF($B3>0,Dashboard!$B$4*IF(Dashboard!$B$5=Dashboard!$B$6,31,((1-Dashboard!$B$5+Dashboard!$B$6)^31-1)/(Dashboard!$B$6-Dashboard!$B$5)),0),""))))) -> 0.11336747 | AH3: =IF(Dashboard!$B$14="Retention %",(1-Dashboard!$B$5)^31,IF(Dashboard!$B$14="MRR ($)",$B3*Dashboard!$B$4*(1-Dashboard!$B$5+Dashboard!$B$6)^31,IF(Dashboard!$B$14="Churned Customers",$B3*(1-(1-Dashboard!$B$5)^31),IF(Dashboard!$B$14="Cumulative Revenue ($)",$B3*Dashboard!$B$4*IF(Dashboard!$B$5=Dashboard!$B$6,32,((1-Dashboard!$B$5+Dashboard!$B$6)^32-1)/(Dashboard!$B$6-Dashboard!$B$5)),IF(Dashboard!$B$14="LTV per Customer ($)",IF($B3>0,Dashboard!$B$4*IF(Dashboard!$B$5=Dashboard!$B$6,32,((1-Dashboard!$B$5+Dashboard!$B$6)^32-1)/(Dashboard!$B$6-Dashboard!$B$5)),0),""))))) -> 0.10543175 | AI3: =IF(Dashboard!$B$14="Retention %",(1-Dashboard!$B$5)^32,IF(Dashboard!$B$14="MRR ($)",$B3*Dashboard!$B$4*(1-Dashboard!$B$5+Dashboard!$B$6)^32,IF(Dashboard!$B$14="Churned Customers",$B3*(1-(1-Dashboard!$B$5)^32),IF(Dashboard!$B$14="Cumulative Revenue ($)",$B3*Dashboard!$B$4*IF(Dashboard!$B$5=Dashboard!$B$6,33,((1-Dashboard!$B$5+Dashboard!$B$6)^33-1)/(Dashboard!$B$6-Dashboard!$B$5)),IF(Dashboard!$B$14="LTV per Customer ($)",IF($B3>0,Dashboard!$B$4*IF(Dashboard!$B$5=Dashboard!$B$6,33,((1-Dashboard!$B$5+Dashboard!$B$6)^33-1)/(Dashboard!$B$6-Dashboard!$B$5)),0),""))))) -> 0.098051525 | AJ3: =IF(Dashboard!$B$14="Retention %",(1-Dashboard!$B$5)^33,IF(Dashboard!$B$14="MRR ($)",$B3*Dashboard!$B$4*(1-Dashboard!$B$5+Dashboard!$B$6)^33,IF(Dashboard!$B$14="Churned Customers",$B3*(1-(1-Dashboard!$B$5)^33),IF(Dashboard!$B$14="Cumulative Revenue ($)",$B3*Dashboard!$B$4*IF(Dashboard!$B$5=Dashboard!$B$6,34,((1-Dashboard!$B$5+Dashboard!$B$6)^34-1)/(Dashboard!$B$6-Dashboard!$B$5)),IF(Dashboard!$B$14="LTV per Customer ($)",IF($B3>0,Dashboard!$B$4*IF(Dashboard!$B$5=Dashboard!$B$6,34,((1-Dashboard!$B$5+Dashboard!$B$6)^34-1)/(Dashboard!$B$6-Dashboard!$B$5)),0),""))))) -> 0.091187918 | AK3: =IF(Dashboard!$B$14="Retention %",(1-Dashboard!$B$5)^34,IF(Dashboard!$B$14="MRR ($)",$B3*Dashboard!$B$4*(1-Dashboard!$B$5+Dashboard!$B$6)^34,IF(Dashboard!$B$14="Churned Customers",$B3*(1-(1-Dashboard!$B$5)^34),IF(Dashboard!$B$14="Cumulative Revenue ($)",$B3*Dashboard!$B$4*IF(Dashboard!$B$5=Dashboard!$B$6,35,((1-Dashboard!$B$5+Dashboard!$B$6)^35-1)/(Dashboard!$B$6-Dashboard!$B$5)),IF(Dashboard!$B$14="LTV per Customer ($)",IF($B3>0,Dashboard!$B$4*IF(Dashboard!$B$5=Dashboard!$B$6,35,((1-Dashboard!$B$5+Dashboard!$B$6)^35-1)/(Dashboard!$B$6-Dashboard!$B$5)),0),""))))) -> 0.084804764 | AL3: =IF(Dashboard!$B$14="Retention %",(1-Dashboard!$B$5)^35,IF(Dashboard!$B$14="MRR ($)",$B3*Dashboard!$B$4*(1-Dashboard!$B$5+Dashboard!$B$6)^35,IF(Dashboard!$B$14="Churned Customers",$B3*(1-(1-Dashboard!$B$5)^35),IF(Dashboard!$B$14="Cumulative Revenue ($)",$B3*Dashboard!$B$4*IF(Dashboard!$B$5=Dashboard!$B$6,36,((1-Dashboard!$B$5+Dashboard!$B$6)^36-1)/(Dashboard!$B$6-Dashboard!$B$5)),IF(Dashboard!$B$14="LTV per Customer ($)",IF($B3>0,Dashboard!$B$4*IF(Dashboard!$B$5=Dashboard!$B$6,36,((1-Dashboard!$B$5+Dashboard!$B$6)^36-1)/(Dashboard!$B$6-Dashboard!$B$5)),0),""))))) -> 0.078868431
A4: Feb '23 Cohort | B4: 1 | C4: =IF(Dashboard!$B$14="Retention %",1,IF(Dashboard!$B$14="MRR ($)",$B4*Dashboard!$B$4,IF(Dashboard!$B$14="Churned Customers",0,IF(Dashboard!$B$14="Cumulative Revenue ($)",$B4*Dashboard!$B$4,IF(Dashboard!$B$14="LTV per Customer ($)",IF($B4>0,Dashboard!$B$4,0),""))))) -> 1 | D4: =IF(Dashboard!$B$14="Retention %",(1-Dashboard!$B$5)^1,IF(Dashboard!$B$14="MRR ($)",$B4*Dashboard!$B$4*(1-Dashboard!$B$5+Dashboard!$B$6)^1,IF(Dashboard!$B$14="Churned Customers",$B4*(1-(1-Dashboard!$B$5)^1),IF(Dashboard!$B$14="Cumulative Revenue ($)",$B4*Dashboard!$B$4*IF(Dashboard!$B$5=Dashboard!$B$6,2,((1-Dashboard!$B$5+Dashboard!$B$6)^2-1)/(Dashboard!$B$6-Dashboard!$B$5)),IF(Dashboard!$B$14="LTV per Customer ($)",IF($B4>0,Dashboard!$B$4*IF(Dashboard!$B$5=Dashboard!$B$6,2,((1-Dashboard!$B$5+Dashboard!$B$6)^2-1)/(Dashboard!$B$6-Dashboard!$B$5)),0),""))))) -> 0.93 | E4: =IF(Dashboard!$B$14="Retention %",(1-Dashboard!$B$5)^2,IF(Dashboard!$B$14="MRR ($)",$B4*Dashboard!$B$4*(1-Dashboard!$B$5+Dashboard!$B$6)^2,IF(Dashboard!$B$14="Churned Customers",$B4*(1-(1-Dashboard!$B$5)^2),IF(Dashboard!$B$14="Cumulative Revenue ($)",$B4*Dashboard!$B$4*IF(Dashboard!$B$5=Dashboard!$B$6,3,((1-Dashboard!$B$5+Dashboard!$B$6)^3-1)/(Dashboard!$B$6-Dashboard!$B$5)),IF(Dashboard!$B$14="LTV per Customer ($)",IF($B4>0,Dashboard!$B$4*IF(Dashboard!$B$5=Dashboard!$B$6,3,((1-Dashboard!$B$5+Dashboard!$B$6)^3-1)/(Dashboard!$B$6-Dashboard!$B$5)),0),""))))) -> 0.8649 | F4: =IF(Dashboard!$B$14="Retention %",(1-Dashboard!$B$5)^3,IF(Dashboard!$B$14="MRR ($)",$B4*Dashboard!$B$4*(1-Dashboard!$B$5+Dashboard!$B$6)^3,IF(Dashboard!$B$14="Churned Customers",$B4*(1-(1-Dashboard!$B$5)^3),IF(Dashboard!$B$14="Cumulative Revenue ($)",$B4*Dashboard!$B$4*IF(Dashboard!$B$5=Dashboard!$B$6,4,((1-Dashboard!$B$5+Dashboard!$B$6)^4-1)/(Dashboard!$B$6-Dashboard!$B$5)),IF(Dashboard!$B$14="LTV per Customer ($)",IF($B4>0,Dashboard!$B$4*IF(Dashboard!$B$5=Dashboard!$B$6,4,((1-Dashboard!$B$5+Dashboard!$B$6)^4-1)/(Dashboard!$B$6-Dashboard!$B$5)),0),""))))) -> 0.804357 | G4: =IF(Dashboard!$B$14="Retention %",(1-Dashboard!$B$5)^4,IF(Dashboard!$B$14="MRR ($)",$B4*Dashboard!$B$4*(1-Dashboard!$B$5+Dashboard!$B$6)^4,IF(Dashboard!$B$14="Churned Customers",$B4*(1-(1-Dashboard!$B$5)^4),IF(Dashboard!$B$14="Cumulative Revenue ($)",$B4*Dashboard!$B$4*IF(Dashboard!$B$5=Dashboard!$B$6,5,((1-Dashboard!$B$5+Dashboard!$B$6)^5-1)/(Dashboard!$B$6-Dashboard!$B$5)),IF(Dashboard!$B$14="LTV per Customer ($)",IF($B4>0,Dashboard!$B$4*IF(Dashboard!$B$5=Dashboard!$B$6,5,((1-Dashboard!$B$5+Dashboard!$B$6)^5-1)/(Dashboard!$B$6-Dashboard!$B$5)),0),""))))) -> 0.74805201 | H4: =IF(Dashboard!$B$14="Retention %",(1-Dashboard!$B$5)^5,IF(Dashboard!$B$14="MRR ($)",$B4*Dashboard!$B$4*(1-Dashboard!$B$5+Dashboard!$B$6)^5,IF(Dashboard!$B$14="Churned Customers",$B4*(1-(1-Dashboard!$B$5)^5),IF(Dashboard!$B$14="Cumulative Revenue ($)",$B4*Dashboard!$B$4*IF(Dashboard!$B$5=Dashboard!$B$6,6,((1-Dashboard!$B$5+Dashboard!$B$6)^6-1)/(Dashboard!$B$6-Dashboard!$B$5)),IF(Dashboard!$B$14="LTV per Customer ($)",IF($B4>0,Dashboard!$B$4*IF(Dashboard!$B$5=Dashboard!$B$6,6,((1-Dashboard!$B$5+Dashboard!$B$6)^6-1)/(Dashboard!$B$6-Dashboard!$B$5)),0),""))))) -> 0.69568837 | I4: =IF(Dashboard!$B$14="Retention %",(1-Dashboard!$B$5)^6,IF(Dashboard!$B$14="MRR ($)",$B4*Dashboard!$B$4*(1-Dashboard!$B$5+Dashboard!$B$6)^6,IF(Dashboard!$B$14="Churned Customers",$B4*(1-(1-Dashboard!$B$5)^6),IF(Dashboard!$B$14="Cumulative Revenue ($)",$B4*Dashboard!$B$4*IF(Dashboard!$B$5=Dashboard!$B$6,7,((1-Dashboard!$B$5+Dashboard!$B$6)^7-1)/(Dashboard!$B$6-Dashboard!$B$5)),IF(Dashboard!$B$14="LTV per Customer ($)",IF($B4>0,Dashboard!$B$4*IF(Dashboard!$B$5=Dashboard!$B$6,7,((1-Dashboard!$B$5+Dashboard!$B$6)^7-1)/(Dashboard!$B$6-Dashboard!$B$5)),0),""))))) -> 0.64699018 | J4: =IF(Dashboard!$B$14="Retention %",(1-Dashboard!$B$5)^7,IF(Dashboard!$B$14="MRR ($)",$B4*Dashboard!$B$4*(1-Dashboard!$B$5+Dashboard!$B$6)^7,IF(Dashboard!$B$14="Churned Customers",$B4*(1-(1-Dashboard!$B$5)^7),IF(Dashboard!$B$14="Cumulative Revenue ($)",$B4*Dashboard!$B$4*IF(Dashboard!$B$5=Dashboard!$B$6,8,((1-Dashboard!$B$5+Dashboard!$B$6)^8-1)/(Dashboard!$B$6-Dashboard!$B$5)),IF(Dashboard!$B$14="LTV per Customer ($)",IF($B4>0,Dashboard!$B$4*IF(Dashboard!$B$5=Dashboard!$B$6,8,((1-Dashboard!$B$5+Dashboard!$B$6)^8-1)/(Dashboard!$B$6-Dashboard!$B$5)),0),""))))) -> 0.60170087 | K4: =IF(Dashboard!$B$14="Retention %",(1-Dashboard!$B$5)^8,IF(Dashboard!$B$14="MRR ($)",$B4*Dashboard!$B$4*(1-Dashboard!$B$5+Dashboard!$B$6)^8,IF(Dashboard!$B$14="Churned Customers",$B4*(1-(1-Dashboard!$B$5)^8),IF(Dashboard!$B$14="Cumulative Revenue ($)",$B4*Dashboard!$B$4*IF(Dashboard!$B$5=Dashboard!$B$6,9,((1-Dashboard!$B$5+Dashboard!$B$6)^9-1)/(Dashboard!$B$6-Dashboard!$B$5)),IF(Dashboard!$B$14="LTV per Customer ($)",IF($B4>0,Dashboard!$B$4*IF(Dashboard!$B$5=Dashboard!$B$6,9,((1-Dashboard!$B$5+Dashboard!$B$6)^9-1)/(Dashboard!$B$6-Dashboard!$B$5)),0),""))))) -> 0.55958181 | L4: =IF(Dashboard!$B$14="Retention %",(1-Dashboard!$B$5)^9,IF(Dashboard!$B$14="MRR ($)",$B4*Dashboard!$B$4*(1-Dashboard!$B$5+Dashboard!$B$6)^9,IF(Dashboard!$B$14="Churned Customers",$B4*(1-(1-Dashboard!$B$5)^9),IF(Dashboard!$B$14="Cumulative Revenue ($)",$B4*Dashboard!$B$4*IF(Dashboard!$B$5=Dashboard!$B$6,10,((1-Dashboard!$B$5+Dashboard!$B$6)^10-1)/(Dashboard!$B$6-Dashboard!$B$5)),IF(Dashboard!$B$14="LTV per Customer ($)",IF($B4>0,Dashboard!$B$4*IF(Dashboard!$B$5=Dashboard!$B$6,10,((1-Dashboard!$B$5+Dashboard!$B$6)^10-1)/(Dashboard!$B$6-Dashboard!$B$5)),0),""))))) -> 0.52041108 | M4: =IF(Dashboard!$B$14="Retention %",(1-Dashboard!$B$5)^10,IF(Dashboard!$B$14="MRR ($)",$B4*Dashboard!$B$4*(1-Dashboard!$B$5+Dashboard!$B$6)^10,IF(Dashboard!$B$14="Churned Customers",$B4*(1-(1-Dashboard!$B$5)^10),IF(Dashboard!$B$14="Cumulative Revenue ($)",$B4*Dashboard!$B$4*IF(Dashboard!$B$5=Dashboard!$B$6,11,((1-Dashboard!$B$5+Dashboard!$B$6)^11-1)/(Dashboard!$B$6-Dashboard!$B$5)),IF(Dashboard!$B$14="LTV per Customer ($)",IF($B4>0,Dashboard!$B$4*IF(Dashboard!$B$5=Dashboard!$B$6,11,((1-Dashboard!$B$5+Dashboard!$B$6)^11-1)/(Dashboard!$B$6-Dashboard!$B$5)),0),""))))) -> 0.48398231 | N4: =IF(Dashboard!$B$14="Retention %",(1-Dashboard!$B$5)^11,IF(Dashboard!$B$14="MRR ($)",$B4*Dashboard!$B$4*(1-Dashboard!$B$5+Dashboard!$B$6)^11,IF(Dashboard!$B$14="Churned Customers",$B4*(1-(1-Dashboard!$B$5)^11),IF(Dashboard!$B$14="Cumulative Revenue ($)",$B4*Dashboard!$B$4*IF(Dashboard!$B$5=Dashboard!$B$6,12,((1-Dashboard!$B$5+Dashboard!$B$6)^12-1)/(Dashboard!$B$6-Dashboard!$B$5)),IF(Dashboard!$B$14="LTV per Customer ($)",IF($B4>0,Dashboard!$B$4*IF(Dashboard!$B$5=Dashboard!$B$6,12,((1-Dashboard!$B$5+Dashboard!$B$6)^12-1)/(Dashboard!$B$6-Dashboard!$B$5)),0),""))))) -> 0.45010355 | O4: =IF(Dashboard!$B$14="Retention %",(1-Dashboard!$B$5)^12,IF(Dashboard!$B$14="MRR ($)",$B4*Dashboard!$B$4*(1-Dashboard!$B$5+Dashboard!$B$6)^12,IF(Dashboard!$B$14="Churned Customers",$B4*(1-(1-Dashboard!$B$5)^12),IF(Dashboard!$B$14="Cumulative Revenue ($)",$B4*Dashboard!$B$4*IF(Dashboard!$B$5=Dashboard!$B$6,13,((1-Dashboard!$B$5+Dashboard!$B$6)^13-1)/(Dashboard!$B$6-Dashboard!$B$5)),IF(Dashboard!$B$14="LTV per Customer ($)",IF($B4>0,Dashboard!$B$4*IF(Dashboard!$B$5=Dashboard!$B$6,13,((1-Dashboard!$B$5+Dashboard!$B$6)^13-1)/(Dashboard!$B$6-Dashboard!$B$5)),0),""))))) -> 0.4185963 | P4: =IF(Dashboard!$B$14="Retention %",(1-Dashboard!$B$5)^13,IF(Dashboard!$B$14="MRR ($)",$B4*Dashboard!$B$4*(1-Dashboard!$B$5+Dashboard!$B$6)^13,IF(Dashboard!$B$14="Churned Customers",$B4*(1-(1-Dashboard!$B$5)^13),IF(Dashboard!$B$14="Cumulative Revenue ($)",$B4*Dashboard!$B$4*IF(Dashboard!$B$5=Dashboard!$B$6,14,((1-Dashboard!$B$5+Dashboard!$B$6)^14-1)/(Dashboard!$B$6-Dashboard!$B$5)),IF(Dashboard!$B$14="LTV per Customer ($)",IF($B4>0,Dashboard!$B$4*IF(Dashboard!$B$5=Dashboard!$B$6,14,((1-Dashboard!$B$5+Dashboard!$B$6)^14-1)/(Dashboard!$B$6-Dashboard!$B$5)),0),""))))) -> 0.38929456 | Q4: =IF(Dashboard!$B$14="Retention %",(1-Dashboard!$B$5)^14,IF(Dashboard!$B$14="MRR ($)",$B4*Dashboard!$B$4*(1-Dashboard!$B$5+Dashboard!$B$6)^14,IF(Dashboard!$B$14="Churned Customers",$B4*(1-(1-Dashboard!$B$5)^14),IF(Dashboard!$B$14="Cumulative Revenue ($)",$B4*Dashboard!$B$4*IF(Dashboard!$B$5=Dashboard!$B$6,15,((1-Dashboard!$B$5+Dashboard!$B$6)^15-1)/(Dashboard!$B$6-Dashboard!$B$5)),IF(Dashboard!$B$14="LTV per Customer ($)",IF($B4>0,Dashboard!$B$4*IF(Dashboard!$B$5=Dashboard!$B$6,15,((1-Dashboard!$B$5+Dashboard!$B$6)^15-1)/(Dashboard!$B$6-Dashboard!$B$5)),0),""))))) -> 0.36204394 | R4: =IF(Dashboard!$B$14="Retention %",(1-Dashboard!$B$5)^15,IF(Dashboard!$B$14="MRR ($)",$B4*Dashboard!$B$4*(1-Dashboard!$B$5+Dashboard!$B$6)^15,IF(Dashboard!$B$14="Churned Customers",$B4*(1-(1-Dashboard!$B$5)^15),IF(Dashboard!$B$14="Cumulative Revenue ($)",$B4*Dashboard!$B$4*IF(Dashboard!$B$5=Dashboard!$B$6,16,((1-Dashboard!$B$5+Dashboard!$B$6)^16-1)/(Dashboard!$B$6-Dashboard!$B$5)),IF(Dashboard!$B$14="LTV per Customer ($)",IF($B4>0,Dashboard!$B$4*IF(Dashboard!$B$5=Dashboard!$B$6,16,((1-Dashboard!$B$5+Dashboard!$B$6)^16-1)/(Dashboard!$B$6-Dashboard!$B$5)),0),""))))) -> 0.33670086 | S4: =IF(Dashboard!$B$14="Retention %",(1-Dashboard!$B$5)^16,IF(Dashboard!$B$14="MRR ($)",$B4*Dashboard!$B$4*(1-Dashboard!$B$5+Dashboard!$B$6)^16,IF(Dashboard!$B$14="Churned Customers",$B4*(1-(1-Dashboard!$B$5)^16),IF(Dashboard!$B$14="Cumulative Revenue ($)",$B4*Dashboard!$B$4*IF(Dashboard!$B$5=Dashboard!$B$6,17,((1-Dashboard!$B$5+Dashboard!$B$6)^17-1)/(Dashboard!$B$6-Dashboard!$B$5)),IF(Dashboard!$B$14="LTV per Customer ($)",IF($B4>0,Dashboard!$B$4*IF(Dashboard!$B$5=Dashboard!$B$6,17,((1-Dashboard!$B$5+Dashboard!$B$6)^17-1)/(Dashboard!$B$6-Dashboard!$B$5)),0),""))))) -> 0.3131318 | T4: =IF(Dashboard!$B$14="Retention %",(1-Dashboard!$B$5)^17,IF(Dashboard!$B$14="MRR ($)",$B4*Dashboard!$B$4*(1-Dashboard!$B$5+Dashboard!$B$6)^17,IF(Dashboard!$B$14="Churned Customers",$B4*(1-(1-Dashboard!$B$5)^17),IF(Dashboard!$B$14="Cumulative Revenue ($)",$B4*Dashboard!$B$4*IF(Dashboard!$B$5=Dashboard!$B$6,18,((1-Dashboard!$B$5+Dashboard!$B$6)^18-1)/(Dashboard!$B$6-Dashboard!$B$5)),IF(Dashboard!$B$14="LTV per Customer ($)",IF($B4>0,Dashboard!$B$4*IF(Dashboard!$B$5=Dashboard!$B$6,18,((1-Dashboard!$B$5+Dashboard!$B$6)^18-1)/(Dashboard!$B$6-Dashboard!$B$5)),0),""))))) -> 0.29121258 | U4: =IF(Dashboard!$B$14="Retention %",(1-Dashboard!$B$5)^18,IF(Dashboard!$B$14="MRR ($)",$B4*Dashboard!$B$4*(1-Dashboard!$B$5+Dashboard!$B$6)^18,IF(Dashboard!$B$14="Churned Customers",$B4*(1-(1-Dashboard!$B$5)^18),IF(Dashboard!$B$14="Cumulative Revenue ($)",$B4*Dashboard!$B$4*IF(Dashboard!$B$5=Dashboard!$B$6,19,((1-Dashboard!$B$5+Dashboard!$B$6)^19-1)/(Dashboard!$B$6-Dashboard!$B$5)),IF(Dashboard!$B$14="LTV per Customer ($)",IF($B4>0,Dashboard!$B$4*IF(Dashboard!$B$5=Dashboard!$B$6,19,((1-Dashboard!$B$5+Dashboard!$B$6)^19-1)/(Dashboard!$B$6-Dashboard!$B$5)),0),""))))) -> 0.2708277 | V4: =IF(Dashboard!$B$14="Retention %",(1-Dashboard!$B$5)^19,IF(Dashboard!$B$14="MRR ($)",$B4*Dashboard!$B$4*(1-Dashboard!$B$5+Dashboard!$B$6)^19,IF(Dashboard!$B$14="Churned Customers",$B4*(1-(1-Dashboard!$B$5)^19),IF(Dashboard!$B$14="Cumulative Revenue ($)",$B4*Dashboard!$B$4*IF(Dashboard!$B$5=Dashboard!$B$6,20,((1-Dashboard!$B$5+Dashboard!$B$6)^20-1)/(Dashboard!$B$6-Dashboard!$B$5)),IF(Dashboard!$B$14="LTV per Customer ($)",IF($B4>0,Dashboard!$B$4*IF(Dashboard!$B$5=Dashboard!$B$6,20,((1-Dashboard!$B$5+Dashboard!$B$6)^20-1)/(Dashboard!$B$6-Dashboard!$B$5)),0),""))))) -> 0.25186976 | W4: =IF(Dashboard!$B$14="Retention %",(1-Dashboard!$B$5)^20,IF(Dashboard!$B$14="MRR ($)",$B4*Dashboard!$B$4*(1-Dashboard!$B$5+Dashboard!$B$6)^20,IF(Dashboard!$B$14="Churned Customers",$B4*(1-(1-Dashboard!$B$5)^20),IF(Dashboard!$B$14="Cumulative Revenue ($)",$B4*Dashboard!$B$4*IF(Dashboard!$B$5=Dashboard!$B$6,21,((1-Dashboard!$B$5+Dashboard!$B$6)^21-1)/(Dashboard!$B$6-Dashboard!$B$5)),IF(Dashboard!$B$14="LTV per Customer ($)",IF($B4>0,Dashboard!$B$4*IF(Dashboard!$B$5=Dashboard!$B$6,21,((1-Dashboard!$B$5+Dashboard!$B$6)^21-1)/(Dashboard!$B$6-Dashboard!$B$5)),0),""))))) -> 0.23423887 | X4: =IF(Dashboard!$B$14="Retention %",(1-Dashboard!$B$5)^21,IF(Dashboard!$B$14="MRR ($)",$B4*Dashboard!$B$4*(1-Dashboard!$B$5+Dashboard!$B$6)^21,IF(Dashboard!$B$14="Churned Customers",$B4*(1-(1-Dashboard!$B$5)^21),IF(Dashboard!$B$14="Cumulative Revenue ($)",$B4*Dashboard!$B$4*IF(Dashboard!$B$5=Dashboard!$B$6,22,((1-Dashboard!$B$5+Dashboard!$B$6)^22-1)/(Dashboard!$B$6-Dashboard!$B$5)),IF(Dashboard!$B$14="LTV per Customer ($)",IF($B4>0,Dashboard!$B$4*IF(Dashboard!$B$5=Dashboard!$B$6,22,((1-Dashboard!$B$5+Dashboard!$B$6)^22-1)/(Dashboard!$B$6-Dashboard!$B$5)),0),""))))) -> 0.21784215 | Y4: =IF(Dashboard!$B$14="Retention %",(1-Dashboard!$B$5)^22,IF(Dashboard!$B$14="MRR ($)",$B4*Dashboard!$B$4*(1-Dashboard!$B$5+Dashboard!$B$6)^22,IF(Dashboard!$B$14="Churned Customers",$B4*(1-(1-Dashboard!$B$5)^22),IF(Dashboard!$B$14="Cumulative Revenue ($)",$B4*Dashboard!$B$4*IF(Dashboard!$B$5=Dashboard!$B$6,23,((1-Dashboard!$B$5+Dashboard!$B$6)^23-1)/(Dashboard!$B$6-Dashboard!$B$5)),IF(Dashboard!$B$14="LTV per Customer ($)",IF($B4>0,Dashboard!$B$4*IF(Dashboard!$B$5=Dashboard!$B$6,23,((1-Dashboard!$B$5+Dashboard!$B$6)^23-1)/(Dashboard!$B$6-Dashboard!$B$5)),0),""))))) -> 0.2025932 | Z4: =IF(Dashboard!$B$14="Retention %",(1-Dashboard!$B$5)^23,IF(Dashboard!$B$14="MRR ($)",$B4*Dashboard!$B$4*(1-Dashboard!$B$5+Dashboard!$B$6)^23,IF(Dashboard!$B$14="Churned Customers",$B4*(1-(1-Dashboard!$B$5)^23),IF(Dashboard!$B$14="Cumulative Revenue ($)",$B4*Dashboard!$B$4*IF(Dashboard!$B$5=Dashboard!$B$6,24,((1-Dashboard!$B$5+Dashboard!$B$6)^24-1)/(Dashboard!$B$6-Dashboard!$B$5)),IF(Dashboard!$B$14="LTV per Customer ($)",IF($B4>0,Dashboard!$B$4*IF(Dashboard!$B$5=Dashboard!$B$6,24,((1-Dashboard!$B$5+Dashboard!$B$6)^24-1)/(Dashboard!$B$6-Dashboard!$B$5)),0),""))))) -> 0.18841168 | AA4: =IF(Dashboard!$B$14="Retention %",(1-Dashboard!$B$5)^24,IF(Dashboard!$B$14="MRR ($)",$B4*Dashboard!$B$4*(1-Dashboard!$B$5+Dashboard!$B$6)^24,IF(Dashboard!$B$14="Churned Customers",$B4*(1-(1-Dashboard!$B$5)^24),IF(Dashboard!$B$14="Cumulative Revenue ($)",$B4*Dashboard!$B$4*IF(Dashboard!$B$5=Dashboard!$B$6,25,((1-Dashboard!$B$5+Dashboard!$B$6)^25-1)/(Dashboard!$B$6-Dashboard!$B$5)),IF(Dashboard!$B$14="LTV per Customer ($)",IF($B4>0,Dashboard!$B$4*IF(Dashboard!$B$5=Dashboard!$B$6,25,((1-Dashboard!$B$5+Dashboard!$B$6)^25-1)/(Dashboard!$B$6-Dashboard!$B$5)),0),""))))) -> 0.17522286 | AB4: =IF(Dashboard!$B$14="Retention %",(1-Dashboard!$B$5)^25,IF(Dashboard!$B$14="MRR ($)",$B4*Dashboard!$B$4*(1-Dashboard!$B$5+Dashboard!$B$6)^25,IF(Dashboard!$B$14="Churned Customers",$B4*(1-(1-Dashboard!$B$5)^25),IF(Dashboard!$B$14="Cumulative Revenue ($)",$B4*Dashboard!$B$4*IF(Dashboard!$B$5=Dashboard!$B$6,26,((1-Dashboard!$B$5+Dashboard!$B$6)^26-1)/(Dashboard!$B$6-Dashboard!$B$5)),IF(Dashboard!$B$14="LTV per Customer ($)",IF($B4>0,Dashboard!$B$4*IF(Dashboard!$B$5=Dashboard!$B$6,26,((1-Dashboard!$B$5+Dashboard!$B$6)^26-1)/(Dashboard!$B$6-Dashboard!$B$5)),0),""))))) -> 0.16295726 | AC4: =IF(Dashboard!$B$14="Retention %",(1-Dashboard!$B$5)^26,IF(Dashboard!$B$14="MRR ($)",$B4*Dashboard!$B$4*(1-Dashboard!$B$5+Dashboard!$B$6)^26,IF(Dashboard!$B$14="Churned Customers",$B4*(1-(1-Dashboard!$B$5)^26),IF(Dashboard!$B$14="Cumulative Revenue ($)",$B4*Dashboard!$B$4*IF(Dashboard!$B$5=Dashboard!$B$6,27,((1-Dashboard!$B$5+Dashboard!$B$6)^27-1)/(Dashboard!$B$6-Dashboard!$B$5)),IF(Dashboard!$B$14="LTV per Customer ($)",IF($B4>0,Dashboard!$B$4*IF(Dashboard!$B$5=Dashboard!$B$6,27,((1-Dashboard!$B$5+Dashboard!$B$6)^27-1)/(Dashboard!$B$6-Dashboard!$B$5)),0),""))))) -> 0.15155025 | AD4: =IF(Dashboard!$B$14="Retention %",(1-Dashboard!$B$5)^27,IF(Dashboard!$B$14="MRR ($)",$B4*Dashboard!$B$4*(1-Dashboard!$B$5+Dashboard!$B$6)^27,IF(Dashboard!$B$14="Churned Customers",$B4*(1-(1-Dashboard!$B$5)^27),IF(Dashboard!$B$14="Cumulative Revenue ($)",$B4*Dashboard!$B$4*IF(Dashboard!$B$5=Dashboard!$B$6,28,((1-Dashboard!$B$5+Dashboard!$B$6)^28-1)/(Dashboard!$B$6-Dashboard!$B$5)),IF(Dashboard!$B$14="LTV per Customer ($)",IF($B4>0,Dashboard!$B$4*IF(Dashboard!$B$5=Dashboard!$B$6,28,((1-Dashboard!$B$5+Dashboard!$B$6)^28-1)/(Dashboard!$B$6-Dashboard!$B$5)),0),""))))) -> 0.14094173 | AE4: =IF(Dashboard!$B$14="Retention %",(1-Dashboard!$B$5)^28,IF(Dashboard!$B$14="MRR ($)",$B4*Dashboard!$B$4*(1-Dashboard!$B$5+Dashboard!$B$6)^28,IF(Dashboard!$B$14="Churned Customers",$B4*(1-(1-Dashboard!$B$5)^28),IF(Dashboard!$B$14="Cumulative Revenue ($)",$B4*Dashboard!$B$4*IF(Dashboard!$B$5=Dashboard!$B$6,29,((1-Dashboard!$B$5+Dashboard!$B$6)^29-1)/(Dashboard!$B$6-Dashboard!$B$5)),IF(Dashboard!$B$14="LTV per Customer ($)",IF($B4>0,Dashboard!$B$4*IF(Dashboard!$B$5=Dashboard!$B$6,29,((1-Dashboard!$B$5+Dashboard!$B$6)^29-1)/(Dashboard!$B$6-Dashboard!$B$5)),0),""))))) -> 0.13107581 | AF4: =IF(Dashboard!$B$14="Retention %",(1-Dashboard!$B$5)^29,IF(Dashboard!$B$14="MRR ($)",$B4*Dashboard!$B$4*(1-Dashboard!$B$5+Dashboard!$B$6)^29,IF(Dashboard!$B$14="Churned Customers",$B4*(1-(1-Dashboard!$B$5)^29),IF(Dashboard!$B$14="Cumulative Revenue ($)",$B4*Dashboard!$B$4*IF(Dashboard!$B$5=Dashboard!$B$6,30,((1-Dashboard!$B$5+Dashboard!$B$6)^30-1)/(Dashboard!$B$6-Dashboard!$B$5)),IF(Dashboard!$B$14="LTV per Customer ($)",IF($B4>0,Dashboard!$B$4*IF(Dashboard!$B$5=Dashboard!$B$6,30,((1-Dashboard!$B$5+Dashboard!$B$6)^30-1)/(Dashboard!$B$6-Dashboard!$B$5)),0),""))))) -> 0.12190051 | AG4: =IF(Dashboard!$B$14="Retention %",(1-Dashboard!$B$5)^30,IF(Dashboard!$B$14="MRR ($)",$B4*Dashboard!$B$4*(1-Dashboard!$B$5+Dashboard!$B$6)^30,IF(Dashboard!$B$14="Churned Customers",$B4*(1-(1-Dashboard!$B$5)^30),IF(Dashboard!$B$14="Cumulative Revenue ($)",$B4*Dashboard!$B$4*IF(Dashboard!$B$5=Dashboard!$B$6,31,((1-Dashboard!$B$5+Dashboard!$B$6)^31-1)/(Dashboard!$B$6-Dashboard!$B$5)),IF(Dashboard!$B$14="LTV per Customer ($)",IF($B4>0,Dashboard!$B$4*IF(Dashboard!$B$5=Dashboard!$B$6,31,((1-Dashboard!$B$5+Dashboard!$B$6)^31-1)/(Dashboard!$B$6-Dashboard!$B$5)),0),""))))) -> 0.11336747 | AH4: =IF(Dashboard!$B$14="Retention %",(1-Dashboard!$B$5)^31,IF(Dashboard!$B$14="MRR ($)",$B4*Dashboard!$B$4*(1-Dashboard!$B$5+Dashboard!$B$6)^31,IF(Dashboard!$B$14="Churned Customers",$B4*(1-(1-Dashboard!$B$5)^31),IF(Dashboard!$B$14="Cumulative Revenue ($)",$B4*Dashboard!$B$4*IF(Dashboard!$B$5=Dashboard!$B$6,32,((1-Dashboard!$B$5+Dashboard!$B$6)^32-1)/(Dashboard!$B$6-Dashboard!$B$5)),IF(Dashboard!$B$14="LTV per Customer ($)",IF($B4>0,Dashboard!$B$4*IF(Dashboard!$B$5=Dashboard!$B$6,32,((1-Dashboard!$B$5+Dashboard!$B$6)^32-1)/(Dashboard!$B$6-Dashboard!$B$5)),0),""))))) -> 0.10543175 | AI4: =IF(Dashboard!$B$14="Retention %",(1-Dashboard!$B$5)^32,IF(Dashboard!$B$14="MRR ($)",$B4*Dashboard!$B$4*(1-Dashboard!$B$5+Dashboard!$B$6)^32,IF(Dashboard!$B$14="Churned Customers",$B4*(1-(1-Dashboard!$B$5)^32),IF(Dashboard!$B$14="Cumulative Revenue ($)",$B4*Dashboard!$B$4*IF(Dashboard!$B$5=Dashboard!$B$6,33,((1-Dashboard!$B$5+Dashboard!$B$6)^33-1)/(Dashboard!$B$6-Dashboard!$B$5)),IF(Dashboard!$B$14="LTV per Customer ($)",IF($B4>0,Dashboard!$B$4*IF(Dashboard!$B$5=Dashboard!$B$6,33,((1-Dashboard!$B$5+Dashboard!$B$6)^33-1)/(Dashboard!$B$6-Dashboard!$B$5)),0),""))))) -> 0.098051525 | AJ4: =IF(Dashboard!$B$14="Retention %",(1-Dashboard!$B$5)^33,IF(Dashboard!$B$14="MRR ($)",$B4*Dashboard!$B$4*(1-Dashboard!$B$5+Dashboard!$B$6)^33,IF(Dashboard!$B$14="Churned Customers",$B4*(1-(1-Dashboard!$B$5)^33),IF(Dashboard!$B$14="Cumulative Revenue ($)",$B4*Dashboard!$B$4*IF(Dashboard!$B$5=Dashboard!$B$6,34,((1-Dashboard!$B$5+Dashboard!$B$6)^34-1)/(Dashboard!$B$6-Dashboard!$B$5)),IF(Dashboard!$B$14="LTV per Customer ($)",IF($B4>0,Dashboard!$B$4*IF(Dashboard!$B$5=Dashboard!$B$6,34,((1-Dashboard!$B$5+Dashboard!$B$6)^34-1)/(Dashboard!$B$6-Dashboard!$B$5)),0),""))))) -> 0.091187918 | AK4: =IF(Dashboard!$B$14="Retention %",(1-Dashboard!$B$5)^34,IF(Dashboard!$B$14="MRR ($)",$B4*Dashboard!$B$4*(1-Dashboard!$B$5+Dashboard!$B$6)^34,IF(Dashboard!$B$14="Churned Customers",$B4*(1-(1-Dashboard!$B$5)^34),IF(Dashboard!$B$14="Cumulative Revenue ($)",$B4*Dashboard!$B$4*IF(Dashboard!$B$5=Dashboard!$B$6,35,((1-Dashboard!$B$5+Dashboard!$B$6)^35-1)/(Dashboard!$B$6-Dashboard!$B$5)),IF(Dashboard!$B$14="LTV per Customer ($)",IF($B4>0,Dashboard!$B$4*IF(Dashboard!$B$5=Dashboard!$B$6,35,((1-Dashboard!$B$5+Dashboard!$B$6)^35-1)/(Dashboard!$B$6-Dashboard!$B$5)),0),""))))) -> 0.084804764
